Workbook

Sheet Do not delete
B1: محضر
B2: توجيه مباشر
B3: إيميل | D3: sources
B4: مهمة روتينية
B9: Performance Analyst
B10: Data Analyst | D10: departments
B11: HASTT
B12: AI
B15: Critical
B16: High | D16: priority
B17: Medium
B18: Low
B20: Annual
B21: Quarterly | D21: frequency
B22: Monthly
B23: Weekly
B25: Completed
B26: In Progress | D26: status
B27: Delayed
B28: Not Started
B30: Done
B31: Not Done | D31: meeting status
B36: Yes
B37: No
B44: Clusters
B45: Committees
B46: Projects | D46: type of meeting
B47: Support Services
B48: External
B49: Others

Sheet User Manual
B1: Performance & Analytics: Operations Health Scoring Model
B2: User Manual
B4: A. | C4: Purpose of the Model
C5: To provide a standardized and objective method for rating a Department’s operational health. This scale enables leadership to:
C6: Identify performance trends, risks, and improvement areas across Tasks, Initiatives, Reports, and Meetings
C7: Support the weekly operations governance cycle and decision-making
B9: B. | C9: How to use this:
C10: Step-1 | D10: Update ONLY following tabs. Complete the green columns in Arabic/English and the orange columns in English only with latest information & Status.
D12: Tasks Tracker | M12: Do Not: (Important Restrictions)
D13: Initiatives | M13: Rename any sheet
D14: Reports | M14: Rename or delete any column
D15: Meetings | M15: Change formulas or formatting
D16: Priorities | M16: Overwrite automatically calculated cells
D17: Weekly Achiever | M17: Add new sheets to the model
C19: Step-2 | D19: Share the updated file with Data & Dashboard team (Hammadi) every Thursday to relfect on the dashboard
B21: C. | C21: Scoring Components
C22: The model evaluates operational health across four key performance dimensions: Tasks, Initiatives, Reports, and Meetings
C23: Each dimension is converted into a 0–5 performance score, weighted, and combined to produce the Overall Health Score
C24: Each category has two scoring components:
C25: 1. Completion Score (0–5)
C26: Based on % Completed + % In-Progress
C27: 2. Delay Score (0–5)
C28: Based on % Delayed
C29: The Final Category Score is a 50–50 weighted average, ensuring the score reflects both:
C30: Speed (completion), and
C31: Discipline (timeliness and delays)
B33: D. | C33: Weighting Structure
C34: Each category contributes differently to the overall score. These weights reflect operational criticality in the vertical
C35: Category | D35: Weight
C36: Tasks | D36: 0.5
C37: Initiatives | D37: 0.2
C38: Reports | D38: 0.2
C39: Meetings | D39: 0.1
B41: E. | C41: Categories for weekly employee recognition
C42: Week 1 | D42: Action Accelerator
C43: Week 2 | D43: Innovation Spark
C44: Week 3 | D44: Extra Miler
C45: Week 4 | D45: Collaboration Legend

Sheet Tasks Tracker
A1: Performance & Analytics: Tasks Tracker
A4: S No. | B4: Source | C4: Description | D4: Department | E4: Start Date | F4: Due Date | G4: Completion % | H4: Status | I4: Priority | J4: Task Owner | K4: Secondery Owner | L4: Under P&A Scope? (Y/N) | M4: If 'No', Specify Responsible Owner | N4: Comments
A5: 1 | C5: متابعة مكتب البيانات بخصوص المطلوب لبحث د. منيرة العيسى | D5: Data Analyst | E5: 46204 | F5: 46209 | G5: 1 | H5: =IF(G5="","",IF(G5=1,"Completed", IF(G5=0,"Not Started", IF(AND(F5<>"",ISNUMBER(F5),F5<TODAY()),"Delayed","In Progress") ) ) ) -> Completed | I5: High | J5: م. حمادي الشعائره | K5: أ. فيصل الرحيمي | L5: Yes | N5: تم ارسال البيانات من حمادي لفيصل
A6: 2 | C6: متابعة تحويل ملف GRC لإدارة أخرى | D6: Performance Analyst | E6: 46198 | F6: 46211 | G6: 0.3 | H6: =IF(G6="","",IF(G6=1,"Completed", IF(G6=0,"Not Started", IF(AND(F6<>"",ISNUMBER(F6),F6<TODAY()),"Delayed","In Progress") ) ) ) -> In Progress | I6: Medium | J6: أ. فيصل الرحيمي | K6: أ. نورة التركي | L6: Yes | N6: تم ارسال تذكير من منار القحطاني لنواف الشثري بخصوص تحديد الممثل
A7: 3 | C7: العمل على تصميم جديد للوحة البيانات | D7: Data Analyst | E7: 46204 | F7: 46208 | G7: 0.5 | H7: =IF(G7="","",IF(G7=1,"Completed", IF(G7=0,"Not Started", IF(AND(F7<>"",ISNUMBER(F7),F7<TODAY()),"Delayed","In Progress") ) ) ) -> Delayed | I7: High | J7: م. حمادي الشعائره | K7: أ. تركي السلمان | L7: Yes | N7: جاري العمل على لوحة البيانات وعمل خطة مشروع لها وللمخرجات
A8: 4 | C8: مناقشة بخصوص التهاب السحايا + استبانة تحديد جنس الجنين اثناء الحمل مع د. منار | D8: Performance Analyst | E8: 46208 | F8: 46210 | G8: 0.2 | H8: =IF(G8="","",IF(G8=1,"Completed", IF(G8=0,"Not Started", IF(AND(F8<>"",ISNUMBER(F8),F8<TODAY()),"Delayed","In Progress") ) ) ) -> Delayed | I8: High | J8: أ. فيصل الرحيمي | K8: أ. نورة التركي | L8: Yes | N8: جاري تحديد موعد مع دكتورة منار
A9: 5 | C9: العمل على متطلبات إدارة السجون + ارسال ايميل د. احمد بخصوص البيانات | D9: Performance Analyst | E9: 46201 | F9: 46208 | G9: 1 | H9: =IF(G9="","",IF(G9=1,"Completed", IF(G9=0,"Not Started", IF(AND(F9<>"",ISNUMBER(F9),F9<TODAY()),"Delayed","In Progress") ) ) ) -> Completed | I9: High | J9: أ. صالحة المالكي | K9: أ. فيصل الرحيمي | L9: Yes | N9: تم اكمال العمل من صالحه جاري المتابعه مع جود
A10: 6 | C10: اكمال مهمة شهادات الإنجاز | D10: Performance Analyst | E10: 46204 | F10: 46208 | G10: 1 | H10: =IF(G10="","",IF(G10=1,"Completed", IF(G10=0,"Not Started", IF(AND(F10<>"",ISNUMBER(F10),F10<TODAY()),"Delayed","In Progress") ) ) ) -> Completed | I10: High | J10: أ. رهف جباري | K10: أ. فيصل الرحيمي | L10: Yes
A11: 7 | C11: العمل على انجاز تأكد | D11: Performance Analyst | E11: 46208 | F11: 46210 | G11: 1 | H11: =IF(G11="","",IF(G11=1,"Completed", IF(G11=0,"Not Started", IF(AND(F11<>"",ISNUMBER(F11),F11<TODAY()),"Delayed","In Progress") ) ) ) -> Completed | I11: Medium | J11: أ. فيصل الرحيمي | K11: أ. نورة التركي | L11: Yes
A12: 8 | C12: العمل على بيانات راصد | D12: Performance Analyst | E12: 46208 | F12: 46211 | G12: 0.5 | H12: =IF(G12="","",IF(G12=1,"Completed", IF(G12=0,"Not Started", IF(AND(F12<>"",ISNUMBER(F12),F12<TODAY()),"Delayed","In Progress") ) ) ) -> In Progress | I12: Medium | J12: أ. نورة التركي | K12: م. علي الزهراني | L12: Yes
A13: 9 | C13: العمل على بيانات نفيس | D13: Data Analyst | E13: 46208 | F13: 46209 | G13: 1 | H13: =IF(G13="","",IF(G13=1,"Completed", IF(G13=0,"Not Started", IF(AND(F13<>"",ISNUMBER(F13),F13<TODAY()),"Delayed","In Progress") ) ) ) -> Completed | I13: Medium | J13: م. حمادي الشعائره | L13: Yes
A14: 10 | C14: عمل خطة مشروع للإدارة للستة اشهر القادمة | D14: Performance Analyst | E14: 46208 | F14: 46210 | G14: 0.5 | H14: =IF(G14="","",IF(G14=1,"Completed", IF(G14=0,"Not Started", IF(AND(F14<>"",ISNUMBER(F14),F14<TODAY()),"Delayed","In Progress") ) ) ) -> Delayed | I14: High | J14: م. علي الزهراني | K14: أ. نورة التركي | L14: Yes
A15: 11 | C15: العمل على آلية انشاء المؤشرات في المركز | D15: Performance Analyst | E15: 46208 | F15: 46213 | G15: 0.1 | H15: =IF(G15="","",IF(G15=1,"Completed", IF(G15=0,"Not Started", IF(AND(F15<>"",ISNUMBER(F15),F15<TODAY()),"Delayed","In Progress") ) ) ) -> In Progress | I15: High | J15: أ. نورة التركي | K15: م. علي الزهراني | L15: Yes
A16: 12 | C16: حصر السياسات وانشاء مؤشرات تنظيمية لها | D16: Performance Analyst | E16: 46204 | F16: 46212 | G16: 0.4 | H16: =IF(G16="","",IF(G16=1,"Completed", IF(G16=0,"Not Started", IF(AND(F16<>"",ISNUMBER(F16),F16<TODAY()),"Delayed","In Progress") ) ) ) -> In Progress | I16: High | J16: أ. صفا الشهري | K16: أ. رهف جباري | L16: Yes | N16: عقد اجتماع مع مرام الشهراني لمناقشة السياسات — مشاركة: أ. صالحة المالكي
A17: 13 | C17: عمل ملخص مهام الأسبوع الأول | D17: Performance Analyst | E17: 46202 | F17: 46204 | G17: 1 | H17: =IF(G17="","",IF(G17=1,"Completed", IF(G17=0,"Not Started", IF(AND(F17<>"",ISNUMBER(F17),F17<TODAY()),"Delayed","In Progress") ) ) ) -> Completed | I17: Medium | J17: أ. نورة التركي | L17: Yes
A18: 14 | C18: عمل نماذج تصاميم للوح البيانات بالهوية الجديدة | D18: Performance Analyst | E18: 46202 | F18: 46204 | G18: 1 | H18: =IF(G18="","",IF(G18=1,"Completed", IF(G18=0,"Not Started", IF(AND(F18<>"",ISNUMBER(F18),F18<TODAY()),"Delayed","In Progress") ) ) ) -> Completed | I18: High | J18: أ. نورة التركي | L18: Yes
A19: 15 | C19: تنظيم آلية العمل داخل الفريق | D19: Performance Analyst | E19: 46209 | F19: 46212 | G19: 0.2 | H19: =IF(G19="","",IF(G19=1,"Completed", IF(G19=0,"Not Started", IF(AND(F19<>"",ISNUMBER(F19),F19<TODAY()),"Delayed","In Progress") ) ) ) -> In Progress | I19: Critical | J19: م. علي الزهراني | K19: أ. نورة التركي
A20: 16 | C20: الاطلاع على نموذج طلب البيانات مع اصايل | D20: Data Analyst | E20: 46209 | F20: 46212 | G20: 0.1 | H20: =IF(G20="","",IF(G20=1,"Completed", IF(G20=0,"Not Started", IF(AND(F20<>"",ISNUMBER(F20),F20<TODAY()),"Delayed","In Progress") ) ) ) -> In Progress | I20: High | J20: م. علي الزهراني
A21: 17 | H21: =IF(G21="","",IF(G21=1,"Completed", IF(G21=0,"Not Started", IF(AND(F21<>"",ISNUMBER(F21),F21<TODAY()),"Delayed","In Progress") ) ) )
A22: 18 | H22: =IF(G22="","",IF(G22=1,"Completed", IF(G22=0,"Not Started", IF(AND(F22<>"",ISNUMBER(F22),F22<TODAY()),"Delayed","In Progress") ) ) )
A23: 19 | H23: =IF(G23="","",IF(G23=1,"Completed", IF(G23=0,"Not Started", IF(AND(F23<>"",ISNUMBER(F23),F23<TODAY()),"Delayed","In Progress") ) ) )
A24: 20 | H24: =IF(G24="","",IF(G24=1,"Completed", IF(G24=0,"Not Started", IF(AND(F24<>"",ISNUMBER(F24),F24<TODAY()),"Delayed","In Progress") ) ) )
A25: 21 | H25: =IF(G25="","",IF(G25=1,"Completed", IF(G25=0,"Not Started", IF(AND(F25<>"",ISNUMBER(F25),F25<TODAY()),"Delayed","In Progress") ) ) )
A26: 22 | H26: =IF(G26="","",IF(G26=1,"Completed", IF(G26=0,"Not Started", IF(AND(F26<>"",ISNUMBER(F26),F26<TODAY()),"Delayed","In Progress") ) ) )
A27: 23 | H27: =IF(G27="","",IF(G27=1,"Completed", IF(G27=0,"Not Started", IF(AND(F27<>"",ISNUMBER(F27),F27<TODAY()),"Delayed","In Progress") ) ) )
A28: 24 | H28: =IF(G28="","",IF(G28=1,"Completed", IF(G28=0,"Not Started", IF(AND(F28<>"",ISNUMBER(F28),F28<TODAY()),"Delayed","In Progress") ) ) )
A29: 25 | H29: =IF(G29="","",IF(G29=1,"Completed", IF(G29=0,"Not Started", IF(AND(F29<>"",ISNUMBER(F29),F29<TODAY()),"Delayed","In Progress") ) ) )
A30: 26 | H30: =IF(G30="","",IF(G30=1,"Completed", IF(G30=0,"Not Started", IF(AND(F30<>"",ISNUMBER(F30),F30<TODAY()),"Delayed","In Progress") ) ) )
A31: 27 | H31: =IF(G31="","",IF(G31=1,"Completed", IF(G31=0,"Not Started", IF(AND(F31<>"",ISNUMBER(F31),F31<TODAY()),"Delayed","In Progress") ) ) )
A32: 28 | H32: =IF(G32="","",IF(G32=1,"Completed", IF(G32=0,"Not Started", IF(AND(F32<>"",ISNUMBER(F32),F32<TODAY()),"Delayed","In Progress") ) ) )
... A108: 104 | H108: =IF(G108="","",IF(G108=1,"Completed", IF(G108=0,"Not Started", IF(AND(F108<>"",ISNUMBER(F108),F108<TODAY()),"Delayed","In Progress") ) ) )
H109: =IF(G109="","",IF(G109=1,"Completed", IF(G109=0,"Not Started", IF(AND(F109<>"",ISNUMBER(F109),F109<TODAY()),"Delayed","In Progress") ) ) )
H110: =IF(G110="","",IF(G110=1,"Completed", IF(G110=0,"Not Started", IF(AND(F110<>"",ISNUMBER(F110),F110<TODAY()),"Delayed","In Progress") ) ) )
H111: =IF(G111="","",IF(G111=1,"Completed", IF(G111=0,"Not Started", IF(AND(F111<>"",ISNUMBER(F111),F111<TODAY()),"Delayed","In Progress") ) ) )
H112: =IF(G112="","",IF(G112=1,"Completed", IF(G112=0,"Not Started", IF(AND(F112<>"",ISNUMBER(F112),F112<TODAY()),"Delayed","In Progress") ) ) )
H113: =IF(G113="","",IF(G113=1,"Completed", IF(G113=0,"Not Started", IF(AND(F113<>"",ISNUMBER(F113),F113<TODAY()),"Delayed","In Progress") ) ) )
H114: =IF(G114="","",IF(G114=1,"Completed", IF(G114=0,"Not Started", IF(AND(F114<>"",ISNUMBER(F114),F114<TODAY()),"Delayed","In Progress") ) ) )
H115: =IF(G115="","",IF(G115=1,"Completed", IF(G115=0,"Not Started", IF(AND(F115<>"",ISNUMBER(F115),F115<TODAY()),"Delayed","In Progress") ) ) )
H116: =IF(G116="","",IF(G116=1,"Completed", IF(G116=0,"Not Started", IF(AND(F116<>"",ISNUMBER(F116),F116<TODAY()),"Delayed","In Progress") ) ) )
H117: =IF(G117="","",IF(G117=1,"Completed", IF(G117=0,"Not Started", IF(AND(F117<>"",ISNUMBER(F117),F117<TODAY()),"Delayed","In Progress") ) ) )
...

Sheet Initiatives
A1: Performance & Analytics: Initiatives Tracker
A4: S No. | B4: Name | C4: Description | D4: Department | E4: Start Date | F4: Due Date | G4: Completion % | H4: Status | I4: Priority | J4: Primary Owner | K4: Secondary Owner | L4: Comments
A5: 1 | B5: إطلاق لوحة بيانات المؤشرات v0 | C5: بناء لوحة المؤشرات على مؤشرات LOC وBTSC القائمة بالهوية الرسمية المعتمدة | D5: Data Analyst | E5: 46204 | F5: 46233 | G5: 0.3 | H5: =IF(G5="","", IF(G5=1,"Completed", IF(G5=0,"Not Started", IF(AND(F5<>"",ISNUMBER(F5),F5<TODAY()),"Delayed","In Progress") ) ) ) -> In Progress | I5: Critical | J5: م. حمادي الشعائره | K5: م. علي الزهراني | L5: الهدف: الإطلاق 30 يوليو — التصميم قيد العمل
A6: =A5+1 -> 2 | B6: آلية دورة حياة المؤشرات ونماذجها | C6: بناء آلية إنشاء واعتماد المؤشرات مع النماذج الأربعة (PA-F01 إلى PA-F04) | D6: Performance Analyst | E6: 46204 | F6: 46219 | G6: 0.6 | H6: =IF(G6="","", IF(G6=1,"Completed", IF(G6=0,"Not Started", IF(AND(F6<>"",ISNUMBER(F6),F6<TODAY()),"Delayed","In Progress") ) ) ) -> In Progress | I6: High | J6: م. علي الزهراني | K6: أ. نورة التركي | L6: النماذج جاهزة — تبقى الموائمة والاعتماد الرسمي
A7: =A6+1 -> 3 | B7: المؤشر التجريبي PA-KPI-001 | C7: تطبيق الآلية كاملة على مؤشر تدوير وحدات الدم بين القطاعات | D7: Performance Analyst | E7: 46208 | F7: 46233 | G7: 0.25 | H7: =IF(G7="","", IF(G7=1,"Completed", IF(G7=0,"Not Started", IF(AND(F7<>"",ISNUMBER(F7),F7<TODAY()),"Delayed","In Progress") ) ) ) -> In Progress | I7: High | J7: م. علي الزهراني | K7: م. حمادي الشعائره | L7: بيانات BBIS متوفرة من القابضة — البطاقة قيد الإعداد
A8: =A7+1 -> 4 | B8: جرد وتوحيد مؤشرات LOC وBTSC | C8: جرد المؤشرات القائمة وتوحيد بطاقاتها على نموذج PA-F02 | D8: Performance Analyst | E8: 46204 | F8: 46225 | G8: 0.35 | H8: =IF(G8="","", IF(G8=1,"Completed", IF(G8=0,"Not Started", IF(AND(F8<>"",ISNUMBER(F8),F8<TODAY()),"Delayed","In Progress") ) ) ) -> In Progress | I8: High | J8: أ. نورة التركي | K8: أ. رهف جباري | L8: قائمة الجرد v1 مستهدفة الخميس 9 يوليو
A9: =A8+1 -> 5 | B9: خريطة مصادر البيانات والوصول | C9: حصر مصادر البيانات وصلاحيات الوصول لكل مؤشرات v0 | D9: Data Analyst | E9: 46204 | F9: 46219 | G9: 0.5 | H9: =IF(G9="","", IF(G9=1,"Completed", IF(G9=0,"Not Started", IF(AND(F9<>"",ISNUMBER(F9),F9<TODAY()),"Delayed","In Progress") ) ) ) -> In Progress | I9: Medium | J9: أ. محمد القحطاني | K9: أ. تركي السلمان
A10: =A9+1 -> 6 | B10: نظام ضبط الوثائق للإدارة | C10: شجرة مجلدات وترميز موحد وسجل صادر/وارد للإدارة | D10: Performance Analyst | E10: 46211 | F10: 46219 | G10: 0.1 | H10: =IF(G10="","", IF(G10=1,"Completed", IF(G10=0,"Not Started", IF(AND(F10<>"",ISNUMBER(F10),F10<TODAY()),"Delayed","In Progress") ) ) ) -> In Progress | I10: Medium | J10: أ. تركي السلمان | K10: م. علي الزهراني | L10: أول ملفين دخلا الترميز الجديد (PLN-001 وPLN-002)
A11: =A10+1 -> 7 | B11: مسودة مجموعة المؤشرات الموحدة | C11: إعداد مسودة المجموعة الموحدة للنقاش تمهيداً لاعتمادها في أغسطس | D11: Performance Analyst | E11: 46222 | F11: 46233 | G11: 0 | H11: =IF(G11="","", IF(G11=1,"Completed", IF(G11=0,"Not Started", IF(AND(F11<>"",ISNUMBER(F11),F11<TODAY()),"Delayed","In Progress") ) ) ) -> Not Started | I11: Medium | J11: أ. نورة التركي | K11: أ. صفا الشهري
A12: =A11+1 -> 8 | H12: =IF(G12="","", IF(G12=1,"Completed", IF(G12=0,"Not Started", IF(AND(F12<>"",ISNUMBER(F12),F12<TODAY()),"Delayed","In Progress") ) ) )
A13: =A12+1 -> 9 | H13: =IF(G13="","", IF(G13=1,"Completed", IF(G13=0,"Not Started", IF(AND(F13<>"",ISNUMBER(F13),F13<TODAY()),"Delayed","In Progress") ) ) )
A14: =A13+1 -> 10 | H14: =IF(G14="","", IF(G14=1,"Completed", IF(G14=0,"Not Started", IF(AND(F14<>"",ISNUMBER(F14),F14<TODAY()),"Delayed","In Progress") ) ) )
H15: =IF(G15="","", IF(G15=1,"Completed", IF(G15=0,"Not Started", IF(AND(F15<>"",ISNUMBER(F15),F15<TODAY()),"Delayed","In Progress") ) ) )
H16: =IF(G16="","", IF(G16=1,"Completed", IF(G16=0,"Not Started", IF(AND(F16<>"",ISNUMBER(F16),F16<TODAY()),"Delayed","In Progress") ) ) )
H17: =IF(G17="","", IF(G17=1,"Completed", IF(G17=0,"Not Started", IF(AND(F17<>"",ISNUMBER(F17),F17<TODAY()),"Delayed","In Progress") ) ) )

Sheet Reports
A1: Performance & Analytics: Key Reports Tracker
A4: S No. | B4: Name | C4: Purpose | D4: Frequency | E4: Department | F4: Start Date | G4: Due Date | H4: Status | I4: Priority | J4: Primary Owner | K4: Secondary Owner | L4: Comments
A5: =ROW()-5 -> 0 | B5: ملف تتبع العمليات (تغذية راصد) | C5: تحديث أسبوعي لمهام ومبادرات وتقارير واجتماعات الإدارة لتغذية لوحة راصد | D5: Weekly | E5: Performance Analyst | F5: 46204 | G5: 46212 | H5: In Progress | I5: High | J5: م. علي الزهراني | K5: أ. نورة التركي | L5: يُسلَّم لفريق البيانات (حمادي) كل خميس
A6: =ROW()-5 -> 1 | B6: ملخص إنجازات الأسبوع | C6: ملخص أسبوعي بإنجازات الفريق ومهامه | D6: Weekly | E6: Performance Analyst | F6: 46202 | G6: 46212 | H6: In Progress | I6: Medium | J6: أ. نورة التركي | L6: ملخص الأسبوع الأول مكتمل
A7: =ROW()-5 -> 2 | B7: حزمة الخميس للمدير | C7: حزمة العرض الأسبوعية لمحطة إقفال الخميس واعتماد المخرجات | D7: Weekly | E7: Performance Analyst | F7: 46208 | G7: 46212 | H7: In Progress | I7: High | J7: م. علي الزهراني | K7: أ. فيصل الرحيمي | L7: هذا الأسبوع: بطاقة PA-KPI-001 + قائمة الجرد
A8: =ROW()-5 -> 3 | B8: تقرير حالة لوحة v0 | C8: تحديث أسبوعي عن تقدم بناء لوحة المؤشرات | D8: Weekly | E8: Data Analyst | F8: 46208 | G8: 46212 | H8: In Progress | I8: Medium | J8: م. حمادي الشعائره
A9: =ROW()-5 -> 4 | B9: تقرير المعايير الدولية للمؤشرات | C9: مقارنة مرجعية بالمعايير الدولية والإقليمية للمؤشرات القائمة | D9: Monthly | E9: Performance Analyst | F9: 46204 | G9: 46216 | H9: In Progress | I9: Medium | J9: أ. صفا الشهري | L9: مدخل لتوحيد مجموعة المؤشرات
A10: =ROW()-5 -> 5
A11: =ROW()-5 -> 6
A12: =ROW()-5 -> 7
A13: =ROW()-5 -> 8
A14: =ROW()-5 -> 9
A15: =ROW()-5 -> 10
A16: =ROW()-5 -> 11
A17: =ROW()-5 -> 12
A18: =ROW()-5 -> 13
A19: =ROW()-5 -> 14
A20: =ROW()-5 -> 15
A21: =ROW()-5 -> 16
... A33: =ROW()-5 -> 28
BD34: Do not Delete
BE35: No. | BF35: %
BD36: Completed | BE36: =COUNTIF(H5:H33,"Completed") -> 0 | BF36: =BE36/(BE$41) -> 0
BD37: In Progress | BE37: =COUNTIF(H5:H33,"In Progress") -> 5 | BF37: =BE37/(BE$41) -> 1
BD38: Delayed | BE38: =COUNTIF(H5:H33,"Delayed") -> 0 | BF38: =BE38/(BE$41) -> 0
BD39: Not Started | BE39: =COUNTIF(H5:H33,"Not Started") -> 0 | BF39: =BE39/(BE$41) -> 0
BD41: Total | BE41: =SUM(BE36:BE39) -> 5

Sheet Meetings
A1: Performance & Analytics: Key Meetings Tracker
A5: S No. | B5: Meeting Name | C5: Purpose | D5: Type of Meeting | E5: Department | F5: Frequency | G5: Schedule | H5: Status - (For current week) | I5: Organizer | J5: Comments | AH5: Do not Delete
A6: 1 | B6: الاجتماع الأسبوعي لفريق الإدارة | C6: متابعة المهام والأولويات وتوزيع العمل | D6: Others | E6: Performance Analyst | F6: Weekly | G6: الأحد صباحاً | H6: Done | I6: م. علي الزهراني | J6: انعقد بداية الأسبوع | AH6: No. | AI6: %
A7: 2 | B7: محطة إقفال الخميس مع المدير (1:1) | C7: عرض مخرجات الأسبوع واعتمادها إدارياً | D7: Others | E7: Performance Analyst | F7: Weekly | G7: كل خميس | H7: Not Done | I7: م. علي الزهراني | J7: خميس 9 يوليو: عرض بطاقة PA-KPI-001 وقائمة الجرد | AG7: Done | AH7: =COUNTIF(H6:H27,"Done") -> 3 | AI7: =IFERROR(AH7/AH9,0) -> 0.42857143
A8: 3 | B8: اجتماع مواءمة السياسات والمعايير والجودة | C8: مواءمة ربط مؤشرات v0 بالسياسات مع إدارة سعيد القحطاني | D8: Others | E8: Performance Analyst | G8: أسبوع 12–15 يوليو | H8: Not Done | I8: م. علي الزهراني | J8: ضمن مرحلة الموائمة | AG8: Not Done | AH8: =COUNTIF(H6:H27,"Not Done") -> 4 | AI8: =IFERROR(AH8/AH9,0) -> 0.57142857
A9: 4 | B9: اجتماع مواءمة الامتثال والتفتيش | C9: قابلية التحقق الميداني للمؤشرات مع إدارة مطلق العتيبي | D9: Others | E9: Performance Analyst | G9: أسبوع 12–15 يوليو | H9: Not Done | I9: م. علي الزهراني | J9: بالتوازي مع مواءمة السياسات | AG9: Total | AH9: =AH7+AH8 -> 7
A10: 5 | B10: اجتماع مناقشة السياسات مع مرام الشهراني | C10: حصر السياسات وإنشاء مؤشرات تنظيمية لها | D10: Others | E10: Performance Analyst | G10: هذا الأسبوع | H10: Done | I10: أ. صفا الشهري | J10: مرتبط بالمهمة رقم 12
A11: 6 | B11: اجتماع مع د. منار | C11: مناقشة التهاب السحايا واستبانة تحديد جنس الجنين أثناء الحمل | D11: External | E11: Performance Analyst | G11: قيد التحديد | H11: Not Done | I11: أ. فيصل الرحيمي | J11: جاري تحديد الموعد — مرتبط بالمهمة رقم 4
A12: 7 | B12: متابعة مكتب البيانات (بحث د. منيرة العيسى) | C12: تسليم البيانات المطلوبة للبحث | D12: External | E12: Data Analyst | G12: مكتمل | H12: Done | I12: م. حمادي الشعائره | J12: تم إرسال البيانات — مرتبط بالمهمة رقم 1
A13: 8
A14: 9
A15: 10
A16: 11
A17: 12
A18: 13
A19: 14
A20: 15
A21: 16
A22: 17
A23: 18
A24: 19
... A27: 22

Sheet Priorities
A1: vertical | B1: taskid | C1: Support
A2: P&A | B2: 15
A3: P&A | B3: 3
A4: P&A | B4: 11
A5: P&A | B5: 12
A6: P&A | B6: 14

Sheet Weekly Achiever
A2: Week 1 | B2: Action Accelerator
A3: Week 2 | B3: Innovation Spark
A4: Week 3 | B4: Extra Miler
A5: Week 4 | B5: Collaboration Legend
C10: Name | D10: أ. نورة التركي
C11: Reason in One line | D11: أنجزت ملخص الأسبوع الأول ونماذج تصاميم اللوحة بالهوية الجديدة في وقتها

Sheet Dashboard Files --

Sheet Health check Model
A1: Health Scoring Model
A3: Model & Scoring Criteria
A6: Metric | B6: Weight (%) | C6: Performance Score (0–5) | D6: Weighted Score | F6: Overall Health Rating Criteria
A7: Tasks | B7: 0.5 | C7: =B19 -> 4 | D7: =B7*C7 -> 2 | F7: Score | G7: Status | H7: Comment
A8: Initiatives | B8: 0.2 | C8: =B30 -> 4.5 | D8: =B8*C8 -> 0.9 | F8: <3 | H8: Critical - Needs Immediate Action
A9: Reports | B9: 0.2 | C9: =B43 -> 5 | D9: =B9*C9 -> 1 | F9: 3 - 4.5 | H9: At Risk - Monitor Closely
A10: Meetings | B10: 0.1 | C10: =B54 -> 0 | D10: =B10*C10 -> 0 | F10: > 4.5 | H10: On Track - Stable
B13: Overall Health Score | D13: =SUM(D7:D10) -> 3.9
A15: Tasks Status & Score
A17: Completion & In-progress Score | B17: =IFERROR(LOOKUP(C22,{0,0.5,0.6,0.7,0.8,0.9},{0,1,2,3,4,5}),"0") -> 4
A18: Delays Score | B18: =IFERROR(LOOKUP(C23,{0,0.101,0.201,0.401,0.501,0.601},{5,4,3,2,1,0}),"0") -> 4
A19: Total Score | B19: =((B17*0.5)+(B18*0.5)) -> 4 | F19: Tasks scoring criteria
F20: % Delayed | G20: Score | H20: Completion % | I20: Score
B21: No. | C21: % | F21: >60% | G21: 0 | H21: <50% | I21: 0
A22: Completed + In progress | B22: =COUNTIFS('Tasks Tracker'!H5:H816,"Completed")+COUNTIFS('Tasks Tracker'!H5:H816,"In Progress") -> 13 | C22: =IFERROR(B22/B25,"0") -> 0.8125 | F22: 50.1%–60% | G22: 1 | H22: 50–60% | I22: 1
A23: Delayed | B23: =COUNTIFS('Tasks Tracker'!H5:H816,"Delayed") -> 3 | C23: =IFERROR(B23/B25,"0") -> 0.1875 | F23: 40.1%–50% | G23: 2 | H23: 60–70% | I23: 2
A24: Not Started | B24: =COUNTIFS('Tasks Tracker'!H5:H816,"Not Started") -> 0 | C24: =IFERROR(B24/B25,"0") -> 0 | F24: 20.1%–40% | G24: 3 | H24: 70–80% | I24: 3
A25: Total | B25: =SUM(B22:B24) -> 16 | F25: 10.1%–20% | G25: 4 | H25: 80–90% | I25: 4
F26: 0%–10% | G26: 5 | H26: ≥90% | I26: 5
A27: Initiatives progress & Score
A28: Completion & On Track Score | B28: =IFERROR(LOOKUP(C33,{0,0.5,0.6,0.7,0.8,0.9},{0,1,2,3,4,5}),"0") -> 4
A29: Delays Score | B29: =IFERROR(LOOKUP(C34,{0,0.101,0.201,0.401,0.501,0.601},{5,4,3,2,1,0}),"0") -> 5
A30: Total Score | B30: =((B28*0.5)+(B29*0.5)) -> 4.5 | F30: Initiatives scoring criteria
F31: % Delayed | G31: Score | H31: Completion % | I31: Score
B32: No. | C32: % | F32: >60% | G32: 0 | H32: <50% | I32: 0
A33: Completed + In Progress | B33: =COUNTIFS(Initiatives!H5:H17,"Completed")+COUNTIFS(Initiatives!H5:H17,"In Progress") -> 6 | C33: =IFERROR(B33/B36,"0") -> 0.85714286 | F33: 50.1%–60% | G33: 1 | H33: 50–60% | I33: 1
A34: Delayed | B34: =COUNTIFS(Initiatives!H5:H17,"Delayed") -> 0 | C34: =IFERROR(B34/B36,"0") -> 0 | F34: 40.1%–50% | G34: 2 | H34: 60–70% | I34: 2
A35: Not Started | B35: =COUNTIFS(Initiatives!H5:H17,"Not Started") -> 1 | C35: =IFERROR(B35/B36,"0") -> 0.14285714 | F35: 20.1%–40% | G35: 3 | H35: 70–80% | I35: 3
A36: Total | B36: =SUM(B33:B35) -> 7 | F36: 10.1%–20% | G36: 4 | H36: 80–90% | I36: 4
F37: 0%–10% | G37: 5 | H37: ≥90% | I37: 5
A40: Reports Status & Score
A41: Completion & In-progress Score | B41: =IFERROR(LOOKUP(C46,{0,0.5,0.6,0.7,0.8,0.9},{0,1,2,3,4,5}),"0") -> 5
A42: Delays Score | B42: =IFERROR(LOOKUP(C47,{0,0.101,0.201,0.401,0.501,0.601},{5,4,3,2,1,0}),"0") -> 5
A43: Score | B43: =((B41*0.5)+(B42*0.5)) -> 5 | F43: Reports scoring criteria
F44: % Delayed | G44: Score | H44: Completion % | I44: Score
B45: No. | C45: % | F45: >60% | G45: 0 | H45: <50% | I45: 0
A46: Completed + In progress | B46: =COUNTIFS(Reports!H5:H33,"Completed")+COUNTIFS(Reports!H5:H33,"In Progress") -> 5 | C46: =IFERROR(B46/B49,"0") -> 1 | F46: 50.1%–60% | G46: 1 | H46: 50–60% | I46: 1
A47: Delayed | B47: =COUNTIFS(Reports!H5:H33,"Delayed") -> 0 | C47: =IFERROR(B47/B49,"0") -> 0 | F47: 40.1%–50% | G47: 2 | H47: 60–70% | I47: 2
A48: Not Started | B48: =COUNTIFS(Reports!H5:H33,"Not Started") -> 0 | C48: =IFERROR(B48/B49,"0") -> 0 | F48: 20.1%–40% | G48: 3 | H48: 70–80% | I48: 3
A49: Total | B49: =SUM(B46:B48) -> 5 | F49: 10.1%–20% | G49: 4 | H49: 80–90% | I49: 4
...

Sheet Health Score
A1: vertical | B1: ID | C1: Metric | D1: Weight (%) | E1: Score | F1: Weighted Score
A2: P&A | B2: 1 | C2: ='Health check Model'!A7 -> Tasks | D2: ='Health check Model'!B7 -> 0.5 | E2: ='Health check Model'!C7 -> 4 | F2: ='Health check Model'!D7 -> 2
A3: P&A | B3: 2 | C3: ='Health check Model'!A8 -> Initiatives | D3: ='Health check Model'!B8 -> 0.2 | E3: ='Health check Model'!C8 -> 4.5 | F3: ='Health check Model'!D8 -> 0.9
A4: P&A | B4: 3 | C4: ='Health check Model'!A9 -> Reports | D4: ='Health check Model'!B9 -> 0.2 | E4: ='Health check Model'!C9 -> 5 | F4: ='Health check Model'!D9 -> 1
A5: P&A | B5: 4 | C5: ='Health check Model'!A10 -> Meetings | D5: ='Health check Model'!B10 -> 0.1 | E5: ='Health check Model'!C10 -> 0 | F5: ='Health check Model'!D10 -> 0

Sheet Tasks Status
B1: ='Tasks Tracker'!BH119 -> No. | C1: ='Tasks Tracker'!BI119 -> %
A2: ='Tasks Tracker'!BG120 -> Completed | B2: ='Tasks Tracker'!BH120 -> 7 | C2: =IFERROR('Tasks Tracker'!BI120,"0") -> 0.4375
A3: ='Tasks Tracker'!BG121 -> In Progress | B3: ='Tasks Tracker'!BH121 -> 6 | C3: =IFERROR('Tasks Tracker'!BI121,"0") -> 0.375
A4: ='Tasks Tracker'!BG122 -> Delayed | B4: ='Tasks Tracker'!BH122 -> 3 | C4: =IFERROR('Tasks Tracker'!BI122,"0") -> 0.1875
A5: ='Tasks Tracker'!BG123 -> Not Started | B5: ='Tasks Tracker'!BH123 -> 0 | C5: =IFERROR('Tasks Tracker'!BI123,"0") -> 0
A6: ='Tasks Tracker'!BG124 -> Total | B6: ='Tasks Tracker'!BH124 -> 16

Sheet Health Score Trend
A1: vertical | B1: Date | C1: score
A2: P&A | B2: 46191 | C2: 3.1
A3: P&A | B3: 46198 | C3: 3.4
A4: P&A | B4: 46205 | C4: 4.6
A5: P&A | B5: 46212 | C5: ='Health check Model'!D13 -> 3.9

Sheet Meetings--
A1: vertical | B1: id | C1: Name | D1: Frequency | E1: Status | F1: Type
A2: P&A | B2: 1 | C2: =Meetings!B6 -> الاجتماع الأسبوعي لفريق الإدارة | D2: =Meetings!F6 -> Weekly | E2: =Meetings!H6 -> Done | F2: =Meetings!D6 -> Others
A3: P&A | B3: 2 | C3: =Meetings!B7 -> محطة إقفال الخميس مع المدير (1:1) | D3: =Meetings!F7 -> Weekly | E3: =Meetings!H7 -> Not Done | F3: =Meetings!D7 -> Others
A4: P&A | B4: 3 | C4: =Meetings!B8 -> اجتماع مواءمة السياسات والمعايير والجودة | D4: =Meetings!F8 -> 0 | E4: =Meetings!H8 -> Not Done | F4: =Meetings!D8 -> Others
A5: P&A | B5: 4 | C5: =Meetings!B9 -> اجتماع مواءمة الامتثال والتفتيش | D5: =Meetings!F9 -> 0 | E5: =Meetings!H9 -> Not Done | F5: =Meetings!D9 -> Others
A6: P&A | B6: 5 | C6: =Meetings!B10 -> اجتماع مناقشة السياسات مع مرام الشهراني | D6: =Meetings!F10 -> 0 | E6: =Meetings!H10 -> Done | F6: =Meetings!D10 -> Others
A7: P&A | B7: 6 | C7: =Meetings!B11 -> اجتماع مع د. منار | D7: =Meetings!F11 -> 0 | E7: =Meetings!H11 -> Not Done | F7: =Meetings!D11 -> External
A8: P&A | B8: 7 | C8: =Meetings!B12 -> متابعة مكتب البيانات (بحث د. منيرة العيسى) | D8: =Meetings!F12 -> 0 | E8: =Meetings!H12 -> Done | F8: =Meetings!D12 -> External
B9: 8 | C9: =Meetings!B13 -> 0 | D9: =Meetings!F13 -> 0 | E9: =Meetings!H13 -> 0 | F9: =Meetings!D13 -> 0
B10: 9 | C10: =Meetings!B14 -> 0 | D10: =Meetings!F14 -> 0 | E10: =Meetings!H14 -> 0 | F10: =Meetings!D14 -> 0
B11: 10 | C11: =Meetings!B15 -> 0 | D11: =Meetings!F15 -> 0 | E11: =Meetings!H15 -> 0 | F11: =Meetings!D15 -> 0
B12: 11 | C12: =Meetings!B16 -> 0 | D12: =Meetings!F16 -> 0 | E12: =Meetings!H16 -> 0 | F12: =Meetings!D16 -> 0
B13: 12 | C13: =Meetings!B17 -> 0 | D13: =Meetings!F17 -> 0 | E13: =Meetings!H17 -> 0 | F13: =Meetings!D17 -> 0
B14: 13 | C14: =Meetings!B18 -> 0 | D14: =Meetings!F18 -> 0 | E14: =Meetings!H18 -> 0 | F14: =Meetings!D18 -> 0
B15: 14 | C15: =Meetings!B19 -> 0 | D15: =Meetings!F19 -> 0 | E15: =Meetings!H19 -> 0 | F15: =Meetings!D19 -> 0
B16: 15 | C16: =Meetings!B20 -> 0 | D16: =Meetings!F20 -> 0 | E16: =Meetings!H20 -> 0 | F16: =Meetings!D20 -> 0
B17: 16 | C17: =Meetings!B21 -> 0 | D17: =Meetings!F21 -> 0 | E17: =Meetings!H21 -> 0 | F17: =Meetings!D21 -> 0
B18: 17 | C18: =Meetings!B22 -> 0 | D18: =Meetings!F22 -> 0 | E18: =Meetings!H22 -> 0 | F18: =Meetings!D22 -> 0
B19: 18 | C19: =Meetings!B23 -> 0 | D19: =Meetings!F23 -> 0 | E19: =Meetings!H23 -> 0 | F19: =Meetings!D23 -> 0
B20: 19 | C20: =Meetings!B24 -> 0 | D20: =Meetings!F24 -> 0 | E20: =Meetings!H24 -> 0 | F20: =Meetings!D24 -> 0
... B23: 22 | C23: =Meetings!B27 -> 0 | D23: =Meetings!F27 -> 0 | E23: =Meetings!H27 -> 0 | F23: =Meetings!D27 -> 0

Sheet Sheet4-Owner names
A1: name | B1: name2
A2: ='Tasks Tracker'!J5 -> م. حمادي الشعائره | B2: ='Tasks Tracker'!J5 -> م. حمادي الشعائره
A3: ='Tasks Tracker'!J6 -> أ. فيصل الرحيمي | B3: ='Tasks Tracker'!J6 -> أ. فيصل الرحيمي
A4: ='Tasks Tracker'!J7 -> م. حمادي الشعائره | B4: ='Tasks Tracker'!J7 -> م. حمادي الشعائره
A5: ='Tasks Tracker'!J8 -> أ. فيصل الرحيمي | B5: ='Tasks Tracker'!J8 -> أ. فيصل الرحيمي
A6: ='Tasks Tracker'!J9 -> أ. صالحة المالكي | B6: ='Tasks Tracker'!J9 -> أ. صالحة المالكي
A7: ='Tasks Tracker'!J10 -> أ. رهف جباري | B7: ='Tasks Tracker'!J10 -> أ. رهف جباري
A8: ='Tasks Tracker'!J11 -> أ. فيصل الرحيمي | B8: ='Tasks Tracker'!J11 -> أ. فيصل الرحيمي
A9: ='Tasks Tracker'!J12 -> أ. نورة التركي | B9: ='Tasks Tracker'!J12 -> أ. نورة التركي
A10: ='Tasks Tracker'!J13 -> م. حمادي الشعائره | B10: ='Tasks Tracker'!J13 -> م. حمادي الشعائره
A11: ='Tasks Tracker'!J14 -> م. علي الزهراني | B11: ='Tasks Tracker'!J14 -> م. علي الزهراني
A12: ='Tasks Tracker'!J15 -> أ. نورة التركي | B12: ='Tasks Tracker'!J15 -> أ. نورة التركي
A13: ='Tasks Tracker'!J16 -> أ. صفا الشهري | B13: ='Tasks Tracker'!J16 -> أ. صفا الشهري
... A102: ='Tasks Tracker'!J105 -> 0 | B102: ='Tasks Tracker'!J105 -> 0

Sheet Department
A2: 1 | B2: Performance Analyst
A3: 2 | B3: Data Analyst
A4: 3 | B4: HASTT
A5: 4 | B5: AI
A8: 1 | B8: 3 | C8: ='Tasks Tracker'!D5 -> Data Analyst
A9: 2 | B9: 2 | C9: ='Tasks Tracker'!D6 -> Performance Analyst
A10: 3 | B10: 3 | C10: ='Tasks Tracker'!D7 -> Data Analyst
A11: 4 | B11: 3 | C11: ='Tasks Tracker'!D8 -> Performance Analyst
A12: 5 | B12: 4 | C12: ='Tasks Tracker'!D9 -> Performance Analyst
A13: 6 | B13: 3 | C13: ='Tasks Tracker'!D10 -> Performance Analyst
A14: 7 | B14: 2 | C14: ='Tasks Tracker'!D11 -> Performance Analyst
A15: 8 | B15: 3 | C15: ='Tasks Tracker'!D12 -> Performance Analyst
A16: 9 | B16: 3 | C16: ='Tasks Tracker'!D13 -> Data Analyst
A17: 10 | B17: 3 | C17: ='Tasks Tracker'!D14 -> Performance Analyst
A18: 11 | B18: 4 | C18: ='Tasks Tracker'!D15 -> Performance Analyst
A19: 12 | B19: 4 | C19: ='Tasks Tracker'!D16 -> Performance Analyst
... A68: 61 | B68: 1 | C68: ='Tasks Tracker'!D65 -> 0
C69: ='Tasks Tracker'!D66 -> 0
C70: ='Tasks Tracker'!D67 -> 0
C71: ='Tasks Tracker'!D68 -> 0
C72: ='Tasks Tracker'!D69 -> 0
C73: ='Tasks Tracker'!D70 -> 0
C74: ='Tasks Tracker'!D71 -> 0
C75: ='Tasks Tracker'!D72 -> 0
C76: ='Tasks Tracker'!D73 -> 0
C77: ='Tasks Tracker'!D74 -> 0
C78: ='Tasks Tracker'!D75 -> 0
C79: ='Tasks Tracker'!D76 -> 0
C80: ='Tasks Tracker'!D77 -> 0
... C108: ='Tasks Tracker'!D105 -> 0

Sheet LastUpdate
A1: LastUpdate
A2: =TODAY() -> 46211
